Workbook

Sheet INÍCIO
B2: GESTÃO DOCUMENTAL — LCQ RJ | K2: DATA DE REFERÊNCIA
B4: Cockpit Executivo de Instruções · Fonte: NDocs Rev.28 | K4: =DataRef -> 46301
B5: Bem-vindo! Escolha abaixo o que você precisa fazer — cada cartão abre a aba certa.
B8: SITUAÇÃO HOJE · carteira completa de instruções
B10: INSTRUÇÕES | E10: APROVADAS | G10: AÇÃO IMEDIATA | J10: VENCEM EM 12 MESES | L10: SAÚDE DOCUMENTAL
B11: =COUNTA('BASE CONSOLIDADA'!$A$5:$A$129) -> 125 | E11: =COUNTIF('BASE CONSOLIDADA'!$N$5:$N$129,"Aprovado") -> 117 | G11: =COUNTIF('BASE CONSOLIDADA'!$R$5:$R$129,"Ação imediata") -> 1 | J11: =COUNTIFS('BASE CONSOLIDADA'!$N$5:$N$129,"Aprovado",'BASE CONSOLIDADA'!$O$5:$O$129,">="&DataRef,'BASE CONSOLIDADA'!$O$5:$O$129,"<="&EDATE(DataRef,12)) -> 12 | L11: =IFERROR((COUNTIF('BASE CONSOLIDADA'!$R$5:$R$129,"Regular")+COUNTIF('BASE CONSOLIDADA'!$R$5:$R$129,"Planejar revisão"))/COUNTIF('BASE CONSOLIDADA'!$R$5:$R$129,"<>Inativo"),0) -> 0.95081967
B12: ="únicas · "&COUNTIF('BASE CONSOLIDADA'!$R$5:$R$129,"<>Inativo")&" ativas" -> únicas · 122 ativas | E12: ="status oficial NDocs" -> status oficial NDocs | G12: ="vencidas e ativas" -> vencidas e ativas | J12: ="planejar revisão" -> planejar revisão | L12: ="aprovadas e válidas ÷ ativas" -> aprovadas e válidas ÷ ativas
B15: O QUE VOCÊ QUER FAZER?
B17: ▦ | F17: ⚑ | J17: ⌕
B18: Ver o panorama geral | F18: Ver o que precisa de ação | J18: Encontrar um documento
B19: Indicadores, riscos, agenda de vencimentos e carteira por área e responsável | F19: Lista curta, priorizada, com a ação recomendada para cada documento | J19: Busque por código NDocs, número antigo (IT …) ou palavra do título
F20: =COUNTIF('BASE CONSOLIDADA'!$U$5:$U$129,">0")&" documento(s) pedem atenção" -> 6 documento(s) pedem atenção
B21: Abrir Dashboard ▸ | F21: Ver ações ▸ | J21: Pesquisar ▸
B23: ☰ | F23: ✓ | J23: ▤
B24: Consultar a base completa | F24: Conferir a qualidade dos dados | J24: Outros controles documentais
B25: Uma linha por código NDocs, com origem rastreável e situação gerencial | F25: Duplicidades, divergências, campos vazios, erros legados e regras de cálculo | J25: FMG/ANX, Transversais, LPP, AST, RT e MO — fora dos KPIs de instruções
B26: =COUNTA('BASE CONSOLIDADA'!$A$5:$A$129)&" códigos únicos" -> 125 códigos únicos | F26: ='QUALIDADE BASE'!E6&" crítico · "&'QUALIDADE BASE'!F6&" atenção" -> 1 crítico · 10 atenção
B27: Abrir Base ▸ | F27: Abrir Qualidade ▸ | J27: Abrir Outros ▸
B30: INSTRUÇÕES POR ÁREA · abas de origem do NDocs
B32: Q4 | E32: PE / PP | H32: AOL | K32: Comuns
B33: =COUNTIF('BASE CONSOLIDADA'!$G$5:$G$129,"*Q4*") -> 61 | E33: =SUMPRODUCT(--((ISNUMBER(SEARCH("PE",'BASE CONSOLIDADA'!$G$5:$G$129))+ISNUMBER(SEARCH("PP",'BASE CONSOLIDADA'!$G$5:$G$129)))>0)) -> 30 | H33: =COUNTIF('BASE CONSOLIDADA'!$G$5:$G$129,"*AOL*") -> 26 | K33: =COUNTIF('BASE CONSOLIDADA'!$G$5:$G$129,"*COMUM*") -> 11
B34: Área Q4 · inclui compartilhadas | E34: PE, PP e PE/PP | H34: Analisadores em linha · inclui Q4/AOL | K34: Comuns ao LCQ
B35: Abrir aba ▸ | E35: Abrir aba ▸ | H35: Abrir aba ▸ | K35: Abrir aba ▸
B37: COMO USAR · 3 passos
B39: 1 | C39: Abra o Dashboard | F39: 2 | G39: Filtre o que importa | J39: 3 | K39: Aprofunde
C40: Veja os números do dia e o painel "Ação necessária agora". | G40: Use as listas suspensas (Área, Situação, Responsável…). Volte a "Todas" para limpar. | K40: Use a Pesquisa ou a Base Consolidada para ver o detalhe de cada documento.
B43: LEGENDA DE CORES | D43: ● Vermelho — agir agora | F43: ● Âmbar — atenção | H43: ● Verde — regular | J43: ● Cinza — inativo
B45: Histórico (versões anteriores, não usadas nos KPIs): abas NDocs, NDocs (2) e NDocs Salvação ▸

Sheet DASHBOARD EXECUTIVO
B2: GESTÃO DOCUMENTAL — LCQ RJ | R2: DATA DE REFERÊNCIA | V2: FONTE
B3: Cockpit Executivo de Instruções | R3: =DataRef -> 46301 | V3: NDocs Rev.28
B4: ⌂ Início | E4: ▦ Dashboard | H4: ⌕ Pesquisa | K4: ☰ Base | N4: ✓ Qualidade | Q4: ▤ Outros | T4: Os filtros abaixo afetam todos os blocos
B6: ÁREA | F6: STATUS NDOCS | J6: SITUAÇÃO GERENCIAL | N6: RESPONSÁVEL | S6: HORIZONTE DE VALIDADE | W6: ↺ Para limpar, volte cada filtro a "Todas/Todos"
B7: Todas | F7: Todos | J7: Todas | N7: Todos | S7: Todos
B9: INSTRUÇÕES ÚNICAS | F9: APROVADAS | J9: EM PROCESSO | N9: AÇÃO IMEDIATA | R9: VENCEM EM 12 MESES | V9: SAÚDE DOCUMENTAL
B10: =SUM('BASE CONSOLIDADA'!$W$5:$W$129) -> 125 | F10: =COUNTIFS('BASE CONSOLIDADA'!$W$5:$W$129,1,'BASE CONSOLIDADA'!$N$5:$N$129,"Aprovado") -> 117 | J10: =COUNTIFS('BASE CONSOLIDADA'!$W$5:$W$129,1,'BASE CONSOLIDADA'!$R$5:$R$129,"Em tratamento") -> 3 | N10: =COUNTIFS('BASE CONSOLIDADA'!$W$5:$W$129,1,'BASE CONSOLIDADA'!$R$5:$R$129,"Ação imediata") -> 1 | R10: =COUNTIFS('BASE CONSOLIDADA'!$W$5:$W$129,1,'BASE CONSOLIDADA'!$N$5:$N$129,"Aprovado",'BASE CONSOLIDADA'!$O$5:$O$129,">="&DataRef,'BASE CONSOLIDADA'!$O$5:$O$129,"<="&EDATE(DataRef,12)) -> 12 | V10: =IFERROR((COUNTIFS('BASE CONSOLIDADA'!$W$5:$W$129,1,'BASE CONSOLIDADA'!$R$5:$R$129,"Regular")+COUNTIFS('BASE CONSOLIDADA'!$W$5:$W$129,1,'BASE CONSOLIDADA'!$R$5:$R$129,"Planejar revisão"))/COUNTIFS('BASE CONSOLIDADA'!$W$5:$W$129,1,'BASE CONSOLIDADA'!$R$5:$R$129,"<>Inativo"),"–") -> 0.95081967
B11: =COUNTIFS('BASE CONSOLIDADA'!$W$5:$W$129,1,'BASE CONSOLIDADA'!$R$5:$R$129,"<>Inativo")&" ativas · "&COUNTIFS('BASE CONSOLIDADA'!$W$5:$W$129,1,'BASE CONSOLIDADA'!$R$5:$R$129,"Inativo")&" inativas" -> 122 ativas · 3 inativas | F11: =IFERROR(TEXT(COUNTIFS('BASE CONSOLIDADA'!$W$5:$W$129,1,'BASE CONSOLIDADA'!$N$5:$N$129,"Aprovado")/COUNTIFS('BASE CONSOLIDADA'!$W$5:$W$129,1,'BASE CONSOLIDADA'!$R$5:$R$129,"<>Inativo"),"0%"),"–")&" das instruções ativas" -> 96% das instruções ativas | J11: ="Revisão "&COUNTIFS('BASE CONSOLIDADA'!$W$5:$W$129,1,'BASE CONSOLIDADA'!$N$5:$N$129,"Revisão")&" · Elaboração "&COUNTIFS('BASE CONSOLIDADA'!$W$5:$W$129,1,'BASE CONSOLIDADA'!$N$5:$N$129,"Em Elaboração") -> Revisão 2 · Elaboração 1 | N11: ="vencida(s) e ativa(s) · +"&COUNTIFS('BASE CONSOLIDADA'!$W$5:$W$129,1,'BASE CONSOLIDADA'!$R$5:$R$129,"Validar cadastro")&" a validar" -> vencida(s) e ativa(s) · +2 a validar | R11: ="até 90 dias: "&COUNTIFS('BASE CONSOLIDADA'!$W$5:$W$129,1,'BASE CONSOLIDADA'!$N$5:$N$129,"Aprovado",'BASE CONSOLIDADA'!$S$5:$S$129,"Até 90 dias") -> até 90 dias: 0 | V11: ="aprovadas e válidas ÷ ativas" -> aprovadas e válidas ÷ ativas
B14: ⚑ AÇÃO NECESSÁRIA AGORA | R14: ◷ AGENDA DE VENCIMENTOS — 12 MESES
B15: Somente o que exige tratamento. Ordem: 1 vencida ativa · 2 não encontrada · 3 revisão · 4 elaboração · 5 vence ≤ 90 dias · 6 validar cadastro | R15: Aprovadas que vencem por mês · barra escura = mês de concentração
B16: P | C16: Código | F16: Título | J16: Área | K16: Situação | M16: Responsável | O16: Ação recomendada
B17: =IF('_AUX DASH'!$C$75="","",INDEX('BASE CONSOLIDADA'!$U$5:$U$129,'_AUX DASH'!$C$75)) -> 1 | C17: =IF('_AUX DASH'!$C$75="","✓ Nenhum item exige ação com os filtros atuais",INDEX('BASE CONSOLIDADA'!$A$5:$A$129,'_AUX DASH'!$C$75)) -> BRK-INS-01-010133-PT | F17: =IF('_AUX DASH'!$C$75="","",INDEX('BASE CONSOLIDADA'!$D$5:$D$129,'_AUX DASH'!$C$75)) -> MANUAL DE SEGURANÇA DO LABORATÓRIO | J17: =IF('_AUX DASH'!$C$75="","",INDEX('BASE CONSOLIDADA'!$G$5:$G$129,'_AUX DASH'!$C$75)) -> COMUM | K17: =IF('_AUX DASH'!$C$75="","",INDEX('BASE CONSOLIDADA'!$R$5:$R$129,'_AUX DASH'!$C$75)) -> Ação imediata | M17: =IF('_AUX DASH'!$C$75="","",INDEX('BASE CONSOLIDADA'!$P$5:$P$129,'_AUX DASH'!$C$75)) -> Ana Carla Da Cruz Araujo | O17: =IF('_AUX DASH'!$C$75="","",INDEX('BASE CONSOLIDADA'!$V$5:$V$129,'_AUX DASH'!$C$75)) -> Revisar ou prorrogar validade
B18: =IF('_AUX DASH'!$C$76="","",INDEX('BASE CONSOLIDADA'!$U$5:$U$129,'_AUX DASH'!$C$76)) -> 2 | C18: =IF('_AUX DASH'!$C$76="","",INDEX('BASE CONSOLIDADA'!$A$5:$A$129,'_AUX DASH'!$C$76)) -> BRK-INS-01-016228-PT | F18: =IF('_AUX DASH'!$C$76="","",INDEX('BASE CONSOLIDADA'!$D$5:$D$129,'_AUX DASH'!$C$76)) -> DETERMINAÇÃO DE CARBONO ORGÂNICO TOTAL (TOC) | J18: =IF('_AUX DASH'!$C$76="","",INDEX('BASE CONSOLIDADA'!$G$5:$G$129,'_AUX DASH'!$C$76)) -> Q4 | K18: =IF('_AUX DASH'!$C$76="","",INDEX('BASE CONSOLIDADA'!$R$5:$R$129,'_AUX DASH'!$C$76)) -> Validar cadastro | M18: =IF('_AUX DASH'!$C$76="","",INDEX('BASE CONSOLIDADA'!$P$5:$P$129,'_AUX DASH'!$C$76)) -> Ana Carla Da Cruz Araujo | O18: =IF('_AUX DASH'!$C$76="","",INDEX('BASE CONSOLIDADA'!$V$5:$V$129,'_AUX DASH'!$C$76)) -> Confirmar status no NDocs
B19: =IF('_AUX DASH'!$C$77="","",INDEX('BASE CONSOLIDADA'!$U$5:$U$129,'_AUX DASH'!$C$77)) -> 3 | C19: =IF('_AUX DASH'!$C$77="","",INDEX('BASE CONSOLIDADA'!$A$5:$A$129,'_AUX DASH'!$C$77)) -> BRK-INS-01-018898-PT | F19: =IF('_AUX DASH'!$C$77="","",INDEX('BASE CONSOLIDADA'!$D$5:$D$129,'_AUX DASH'!$C$77)) -> DETERMINAÇÃO DE ÓLEOS E GRAXAS | J19: =IF('_AUX DASH'!$C$77="","",INDEX('BASE CONSOLIDADA'!$G$5:$G$129,'_AUX DASH'!$C$77)) -> Q4 | K19: =IF('_AUX DASH'!$C$77="","",INDEX('BASE CONSOLIDADA'!$R$5:$R$129,'_AUX DASH'!$C$77)) -> Em tratamento | M19: =IF('_AUX DASH'!$C$77="","",INDEX('BASE CONSOLIDADA'!$P$5:$P$129,'_AUX DASH'!$C$77)) -> Ana Carla Da Cruz Araujo | O19: =IF('_AUX DASH'!$C$77="","",INDEX('BASE CONSOLIDADA'!$V$5:$V$129,'_AUX DASH'!$C$77)) -> Acompanhar revisão
B20: =IF('_AUX DASH'!$C$78="","",INDEX('BASE CONSOLIDADA'!$U$5:$U$129,'_AUX DASH'!$C$78)) -> 3 | C20: =IF('_AUX DASH'!$C$78="","",INDEX('BASE CONSOLIDADA'!$A$5:$A$129,'_AUX DASH'!$C$78)) -> BRK-INS-01-013358-PT | F20: =IF('_AUX DASH'!$C$78="","",INDEX('BASE CONSOLIDADA'!$D$5:$D$129,'_AUX DASH'!$C$78)) -> DETERMINAÇÃO DO TEOR DE SOLÚVEIS EM XILENO TOTAL, AMORFO E OLIGÔMEROS | J20: =IF('_AUX DASH'!$C$78="","",INDEX('BASE CONSOLIDADA'!$G$5:$G$129,'_AUX DASH'!$C$78)) -> PP | K20: =IF('_AUX DASH'!$C$78="","",INDEX('BASE CONSOLIDADA'!$R$5:$R$129,'_AUX DASH'!$C$78)) -> Em tratamento | M20: =IF('_AUX DASH'!$C$78="","",INDEX('BASE CONSOLIDADA'!$P$5:$P$129,'_AUX DASH'!$C$78)) -> Bruna Luisa Goldschmidt | O20: =IF('_AUX DASH'!$C$78="","",INDEX('BASE CONSOLIDADA'!$V$5:$V$129,'_AUX DASH'!$C$78)) -> Acompanhar revisão
B21: =IF('_AUX DASH'!$C$79="","",INDEX('BASE CONSOLIDADA'!$U$5:$U$129,'_AUX DASH'!$C$79)) -> 4 | C21: =IF('_AUX DASH'!$C$79="","",INDEX('BASE CONSOLIDADA'!$A$5:$A$129,'_AUX DASH'!$C$79)) -> BRK-INS-01-015837-PT | F21: =IF('_AUX DASH'!$C$79="","",INDEX('BASE CONSOLIDADA'!$D$5:$D$129,'_AUX DASH'!$C$79)) -> DETERMINAÇÃO DE INORGÂNICOS POR CROMATOGRAFIA GASOSA | J21: =IF('_AUX DASH'!$C$79="","",INDEX('BASE CONSOLIDADA'!$G$5:$G$129,'_AUX DASH'!$C$79)) -> Q4 | K21: =IF('_AUX DASH'!$C$79="","",INDEX('BASE CONSOLIDADA'!$R$5:$R$129,'_AUX DASH'!$C$79)) -> Em tratamento | M21: =IF('_AUX DASH'!$C$79="","",INDEX('BASE CONSOLIDADA'!$P$5:$P$129,'_AUX DASH'!$C$79)) -> Isabel Teixeira Malvar Pinto | O21: =IF('_AUX DASH'!$C$79="","",INDEX('BASE CONSOLIDADA'!$V$5:$V$129,'_AUX DASH'!$C$79)) -> Concluir elaboração
B22: =IF('_AUX DASH'!$C$80="","",INDEX('BASE CONSOLIDADA'!$U$5:$U$129,'_AUX DASH'!$C$80)) -> 6 | C22: =IF('_AUX DASH'!$C$80="","",INDEX('BASE CONSOLIDADA'!$A$5:$A$129,'_AUX DASH'!$C$80)) -> BRK-INS-01-012704-PT | F22: =IF('_AUX DASH'!$C$80="","",INDEX('BASE CONSOLIDADA'!$D$5:$D$129,'_AUX DASH'!$C$80)) -> ONTROLE DE QUALIDADE DE RESINAS DE PE, PP E EVA - REGIONAL RS | J22: =IF('_AUX DASH'!$C$80="","",INDEX('BASE CONSOLIDADA'!$G$5:$G$129,'_AUX DASH'!$C$80)) -> PE/PP | K22: =IF('_AUX DASH'!$C$80="","",INDEX('BASE CONSOLIDADA'!$R$5:$R$129,'_AUX DASH'!$C$80)) -> Validar cadastro | M22: =IF('_AUX DASH'!$C$80="","",INDEX('BASE CONSOLIDADA'!$P$5:$P$129,'_AUX DASH'!$C$80)) -> Cleiton Leandro Zimmermann Pereira | O22: =IF('_AUX DASH'!$C$80="","",INDEX('BASE CONSOLIDADA'!$V$5:$V$129,'_AUX DASH'!$C$80)) -> Validar aplicabilidade
B23: =IF('_AUX DASH'!$C$81="","",INDEX('BASE CONSOLIDADA'!$U$5:$U$129,'_AUX DASH'!$C$81)) | C23: =IF('_AUX DASH'!$C$81="","",INDEX('BASE CONSOLIDADA'!$A$5:$A$129,'_AUX DASH'!$C$81)) | F23: =IF('_AUX DASH'!$C$81="","",INDEX('BASE CONSOLIDADA'!$D$5:$D$129,'_AUX DASH'!$C$81)) | J23: =IF('_AUX DASH'!$C$81="","",INDEX('BASE CONSOLIDADA'!$G$5:$G$129,'_AUX DASH'!$C$81)) | K23: =IF('_AUX DASH'!$C$81="","",INDEX('BASE CONSOLIDADA'!$R$5:$R$129,'_AUX DASH'!$C$81)) | M23: =IF('_AUX DASH'!$C$81="","",INDEX('BASE CONSOLIDADA'!$P$5:$P$129,'_AUX DASH'!$C$81)) | O23: =IF('_AUX DASH'!$C$81="","",INDEX('BASE CONSOLIDADA'!$V$5:$V$129,'_AUX DASH'!$C$81))
B24: =IF('_AUX DASH'!$C$82="","",INDEX('BASE CONSOLIDADA'!$U$5:$U$129,'_AUX DASH'!$C$82)) | C24: =IF('_AUX DASH'!$C$82="","",INDEX('BASE CONSOLIDADA'!$A$5:$A$129,'_AUX DASH'!$C$82)) | F24: =IF('_AUX DASH'!$C$82="","",INDEX('BASE CONSOLIDADA'!$D$5:$D$129,'_AUX DASH'!$C$82)) | J24: =IF('_AUX DASH'!$C$82="","",INDEX('BASE CONSOLIDADA'!$G$5:$G$129,'_AUX DASH'!$C$82)) | K24: =IF('_AUX DASH'!$C$82="","",INDEX('BASE CONSOLIDADA'!$R$5:$R$129,'_AUX DASH'!$C$82)) | M24: =IF('_AUX DASH'!$C$82="","",INDEX('BASE CONSOLIDADA'!$P$5:$P$129,'_AUX DASH'!$C$82)) | O24: =IF('_AUX DASH'!$C$82="","",INDEX('BASE CONSOLIDADA'!$V$5:$V$129,'_AUX DASH'!$C$82))
B27: ▤ CARTEIRA POR ÁREA | J27: ▦ MATRIZ ÁREA × SITUAÇÃO | S27: ◉ CARTEIRA POR RESPONSÁVEL
B28: Código único · compartilhados em categoria própria | J28: Onde está concentrado o risco | S28: Para acompanhamento — não é ranking de desempenho
J29: Área | L29: Ação imed. | M29: Validar | N29: Em trat. | O29: Planejar | P29: Regular | Q29: Inativo | S29: Responsável | V29: Total | W29: Em trat. | X29: Ação/ valid. | Y29: 12 m
J30: Q4 | L30: =COUNTIFS('BASE CONSOLIDADA'!$W$5:$W$129,1,'BASE CONSOLIDADA'!$G$5:$G$129,$J30,'BASE CONSOLIDADA'!$R$5:$R$129,"Ação imediata") -> 0 | M30: =COUNTIFS('BASE CONSOLIDADA'!$W$5:$W$129,1,'BASE CONSOLIDADA'!$G$5:$G$129,$J30,'BASE CONSOLIDADA'!$R$5:$R$129,"Validar cadastro") -> 1 | N30: =COUNTIFS('BASE CONSOLIDADA'!$W$5:$W$129,1,'BASE CONSOLIDADA'!$G$5:$G$129,$J30,'BASE CONSOLIDADA'!$R$5:$R$129,"Em tratamento") -> 2 | O30: =COUNTIFS('BASE CONSOLIDADA'!$W$5:$W$129,1,'BASE CONSOLIDADA'!$G$5:$G$129,$J30,'BASE CONSOLIDADA'!$R$5:$R$129,"Planejar revisão") -> 2 | P30: =COUNTIFS('BASE CONSOLIDADA'!$W$5:$W$129,1,'BASE CONSOLIDADA'!$G$5:$G$129,$J30,'BASE CONSOLIDADA'!$R$5:$R$129,"Regular") -> 51 | Q30: =COUNTIFS('BASE CONSOLIDADA'!$W$5:$W$129,1,'BASE CONSOLIDADA'!$G$5:$G$129,$J30,'BASE CONSOLIDADA'!$R$5:$R$129,"Inativo") -> 2 | S30: =IF('_AUX DASH'!$J$50="","",INDEX('_AUX DASH'!$K$50:$K$69,'_AUX DASH'!$J$50)) -> Ana Araujo | V30: =IF('_AUX DASH'!$J$50="","",INDEX('_AUX DASH'!$B$50:$B$69,'_AUX DASH'!$J$50)) -> 46 | W30: =IF('_AUX DASH'!$J$50="","",INDEX('_AUX DASH'!$C$50:$C$69,'_AUX DASH'!$J$50)) -> 1 | X30: =IF('_AUX DASH'!$J$50="","",INDEX('_AUX DASH'!$D$50:$D$69,'_AUX DASH'!$J$50)) -> 2 | Y30: =IF('_AUX DASH'!$J$50="","",INDEX('_AUX DASH'!$E$50:$E$69,'_AUX DASH'!$J$50)) -> 3
J31: AOL | L31: =COUNTIFS('BASE CONSOLIDADA'!$W$5:$W$129,1,'BASE CONSOLIDADA'!$G$5:$G$129,$J31,'BASE CONSOLIDADA'!$R$5:$R$129,"Ação imediata") -> 0 | M31: =COUNTIFS('BASE CONSOLIDADA'!$W$5:$W$129,1,'BASE CONSOLIDADA'!$G$5:$G$129,$J31,'BASE CONSOLIDADA'!$R$5:$R$129,"Validar cadastro") -> 0 | N31: =COUNTIFS('BASE CONSOLIDADA'!$W$5:$W$129,1,'BASE CONSOLIDADA'!$G$5:$G$129,$J31,'BASE CONSOLIDADA'!$R$5:$R$129,"Em tratamento") -> 0 | O31: =COUNTIFS('BASE CONSOLIDADA'!$W$5:$W$129,1,'BASE CONSOLIDADA'!$G$5:$G$129,$J31,'BASE CONSOLIDADA'!$R$5:$R$129,"Planejar revisão") -> 3 | P31: =COUNTIFS('BASE CONSOLIDADA'!$W$5:$W$129,1,'BASE CONSOLIDADA'!$G$5:$G$129,$J31,'BASE CONSOLIDADA'!$R$5:$R$129,"Regular") -> 20 | Q31: =COUNTIFS('BASE CONSOLIDADA'!$W$5:$W$129,1,'BASE CONSOLIDADA'!$G$5:$G$129,$J31,'BASE CONSOLIDADA'!$R$5:$R$129,"Inativo") -> 0 | S31: =IF('_AUX DASH'!$J$51="","",INDEX('_AUX DASH'!$K$50:$K$69,'_AUX DASH'!$J$51)) -> Cleiton Pereira | V31: =IF('_AUX DASH'!$J$51="","",INDEX('_AUX DASH'!$B$50:$B$69,'_AUX DASH'!$J$51)) -> 1 | W31: =IF('_AUX DASH'!$J$51="","",INDEX('_AUX DASH'!$C$50:$C$69,'_AUX DASH'!$J$51)) -> 0 | X31: =IF('_AUX DASH'!$J$51="","",INDEX('_AUX DASH'!$D$50:$D$69,'_AUX DASH'!$J$51)) -> 1 | Y31: =IF('_AUX DASH'!$J$51="","",INDEX('_AUX DASH'!$E$50:$E$69,'_AUX DASH'!$J$51)) -> 0
J32: PE | L32: =COUNTIFS('BASE CONSOLIDADA'!$W$5:$W$129,1,'BASE CONSOLIDADA'!$G$5:$G$129,$J32,'BASE CONSOLIDADA'!$R$5:$R$129,"Ação imediata") -> 0 | M32: =COUNTIFS('BASE CONSOLIDADA'!$W$5:$W$129,1,'BASE CONSOLIDADA'!$G$5:$G$129,$J32,'BASE CONSOLIDADA'!$R$5:$R$129,"Validar cadastro") -> 0 | N32: =COUNTIFS('BASE CONSOLIDADA'!$W$5:$W$129,1,'BASE CONSOLIDADA'!$G$5:$G$129,$J32,'BASE CONSOLIDADA'!$R$5:$R$129,"Em tratamento") -> 0 | O32: =COUNTIFS('BASE CONSOLIDADA'!$W$5:$W$129,1,'BASE CONSOLIDADA'!$G$5:$G$129,$J32,'BASE CONSOLIDADA'!$R$5:$R$129,"Planejar revisão") -> 1 | P32: =COUNTIFS('BASE CONSOLIDADA'!$W$5:$W$129,1,'BASE CONSOLIDADA'!$G$5:$G$129,$J32,'BASE CONSOLIDADA'!$R$5:$R$129,"Regular") -> 10 | Q32: =COUNTIFS('BASE CONSOLIDADA'!$W$5:$W$129,1,'BASE CONSOLIDADA'!$G$5:$G$129,$J32,'BASE CONSOLIDADA'!$R$5:$R$129,"Inativo") -> 0 | S32: =IF('_AUX DASH'!$J$52="","",INDEX('_AUX DASH'!$K$50:$K$69,'_AUX DASH'!$J$52)) -> Isabel Pinto | V32: =IF('_AUX DASH'!$J$52="","",INDEX('_AUX DASH'!$B$50:$B$69,'_AUX DASH'!$J$52)) -> 2 | W32: =IF('_AUX DASH'!$J$52="","",INDEX('_AUX DASH'!$C$50:$C$69,'_AUX DASH'!$J$52)) -> 1 | X32: =IF('_AUX DASH'!$J$52="","",INDEX('_AUX DASH'!$D$50:$D$69,'_AUX DASH'!$J$52)) -> 0 | Y32: =IF('_AUX DASH'!$J$52="","",INDEX('_AUX DASH'!$E$50:$E$69,'_AUX DASH'!$J$52)) -> 0
J33: COMUM | L33: =COUNTIFS('BASE CONSOLIDADA'!$W$5:$W$129,1,'BASE CONSOLIDADA'!$G$5:$G$129,$J33,'BASE CONSOLIDADA'!$R$5:$R$129,"Ação imediata") -> 1 | M33: =COUNTIFS('BASE CONSOLIDADA'!$W$5:$W$129,1,'BASE CONSOLIDADA'!$G$5:$G$129,$J33,'BASE CONSOLIDADA'!$R$5:$R$129,"Validar cadastro") -> 0 | N33: =COUNTIFS('BASE CONSOLIDADA'!$W$5:$W$129,1,'BASE CONSOLIDADA'!$G$5:$G$129,$J33,'BASE CONSOLIDADA'!$R$5:$R$129,"Em tratamento") -> 0 | O33: =COUNTIFS('BASE CONSOLIDADA'!$W$5:$W$129,1,'BASE CONSOLIDADA'!$G$5:$G$129,$J33,'BASE CONSOLIDADA'!$R$5:$R$129,"Planejar revisão") -> 3 | P33: =COUNTIFS('BASE CONSOLIDADA'!$W$5:$W$129,1,'BASE CONSOLIDADA'!$G$5:$G$129,$J33,'BASE CONSOLIDADA'!$R$5:$R$129,"Regular") -> 7 | Q33: =COUNTIFS('BASE CONSOLIDADA'!$W$5:$W$129,1,'BASE CONSOLIDADA'!$G$5:$G$129,$J33,'BASE CONSOLIDADA'!$R$5:$R$129,"Inativo") -> 0 | S33: =IF('_AUX DASH'!$J$53="","",INDEX('_AUX DASH'!$K$50:$K$69,'_AUX DASH'!$J$53)) -> Bruna Goldschmidt | V33: =IF('_AUX DASH'!$J$53="","",INDEX('_AUX DASH'!$B$50:$B$69,'_AUX DASH'!$J$53)) -> 1 | W33: =IF('_AUX DASH'!$J$53="","",INDEX('_AUX DASH'!$C$50:$C$69,'_AUX DASH'!$J$53)) -> 1 | X33: =IF('_AUX DASH'!$J$53="","",INDEX('_AUX DASH'!$D$50:$D$69,'_AUX DASH'!$J$53)) -> 0 | Y33: =IF('_AUX DASH'!$J$53="","",INDEX('_AUX DASH'!$E$50:$E$69,'_AUX DASH'!$J$53)) -> 0
J34: PP | L34: =COUNTIFS('BASE CONSOLIDADA'!$W$5:$W$129,1,'BASE CONSOLIDADA'!$G$5:$G$129,$J34,'BASE CONSOLIDADA'!$R$5:$R$129,"Ação imediata") -> 0 | M34: =COUNTIFS('BASE CONSOLIDADA'!$W$5:$W$129,1,'BASE CONSOLIDADA'!$G$5:$G$129,$J34,'BASE CONSOLIDADA'!$R$5:$R$129,"Validar cadastro") -> 0 | N34: =COUNTIFS('BASE CONSOLIDADA'!$W$5:$W$129,1,'BASE CONSOLIDADA'!$G$5:$G$129,$J34,'BASE CONSOLIDADA'!$R$5:$R$129,"Em tratamento") -> 1 | O34: =COUNTIFS('BASE CONSOLIDADA'!$W$5:$W$129,1,'BASE CONSOLIDADA'!$G$5:$G$129,$J34,'BASE CONSOLIDADA'!$R$5:$R$129,"Planejar revisão") -> 2 | P34: =COUNTIFS('BASE CONSOLIDADA'!$W$5:$W$129,1,'BASE CONSOLIDADA'!$G$5:$G$129,$J34,'BASE CONSOLIDADA'!$R$5:$R$129,"Regular") -> 6 | Q34: =COUNTIFS('BASE CONSOLIDADA'!$W$5:$W$129,1,'BASE CONSOLIDADA'!$G$5:$G$129,$J34,'BASE CONSOLIDADA'!$R$5:$R$129,"Inativo") -> 1 | S34: =IF('_AUX DASH'!$J$54="","",INDEX('_AUX DASH'!$K$50:$K$69,'_AUX DASH'!$J$54)) -> Ana Oliveira | V34: =IF('_AUX DASH'!$J$54="","",INDEX('_AUX DASH'!$B$50:$B$69,'_AUX DASH'!$J$54)) -> 26 | W34: =IF('_AUX DASH'!$J$54="","",INDEX('_AUX DASH'!$C$50:$C$69,'_AUX DASH'!$J$54)) -> 0 | X34: =IF('_AUX DASH'!$J$54="","",INDEX('_AUX DASH'!$D$50:$D$69,'_AUX DASH'!$J$54)) -> 0 | Y34: =IF('_AUX DASH'!$J$54="","",INDEX('_AUX DASH'!$E$50:$E$69,'_AUX DASH'!$J$54)) -> 3
J35: PE/PP | L35: =COUNTIFS('BASE CONSOLIDADA'!$W$5:$W$129,1,'BASE CONSOLIDADA'!$G$5:$G$129,$J35,'BASE CONSOLIDADA'!$R$5:$R$129,"Ação imediata") -> 0 | M35: =COUNTIFS('BASE CONSOLIDADA'!$W$5:$W$129,1,'BASE CONSOLIDADA'!$G$5:$G$129,$J35,'BASE CONSOLIDADA'!$R$5:$R$129,"Validar cadastro") -> 1 | N35: =COUNTIFS('BASE CONSOLIDADA'!$W$5:$W$129,1,'BASE CONSOLIDADA'!$G$5:$G$129,$J35,'BASE CONSOLIDADA'!$R$5:$R$129,"Em tratamento") -> 0 | O35: =COUNTIFS('BASE CONSOLIDADA'!$W$5:$W$129,1,'BASE CONSOLIDADA'!$G$5:$G$129,$J35,'BASE CONSOLIDADA'!$R$5:$R$129,"Planejar revisão") -> 1 | P35: =COUNTIFS('BASE CONSOLIDADA'!$W$5:$W$129,1,'BASE CONSOLIDADA'!$G$5:$G$129,$J35,'BASE CONSOLIDADA'!$R$5:$R$129,"Regular") -> 7 | Q35: =COUNTIFS('BASE CONSOLIDADA'!$W$5:$W$129,1,'BASE CONSOLIDADA'!$G$5:$G$129,$J35,'BASE CONSOLIDADA'!$R$5:$R$129,"Inativo") -> 0 | S35: =IF('_AUX DASH'!$J$55="","",INDEX('_AUX DASH'!$K$50:$K$69,'_AUX DASH'!$J$55)) -> Fatima Guterres | V35: =IF('_AUX DASH'!$J$55="","",INDEX('_AUX DASH'!$B$50:$B$69,'_AUX DASH'!$J$55)) -> 11 | W35: =IF('_AUX DASH'!$J$55="","",INDEX('_AUX DASH'!$C$50:$C$69,'_AUX DASH'!$J$55)) -> 0 | X35: =IF('_AUX DASH'!$J$55="","",INDEX('_AUX DASH'!$D$50:$D$69,'_AUX DASH'!$J$55)) -> 0 | Y35: =IF('_AUX DASH'!$J$55="","",INDEX('_AUX DASH'!$E$50:$E$69,'_AUX DASH'!$J$55)) -> 2
J36: Q4/AOL | L36: =COUNTIFS('BASE CONSOLIDADA'!$W$5:$W$129,1,'BASE CONSOLIDADA'!$G$5:$G$129,$J36,'BASE CONSOLIDADA'!$R$5:$R$129,"Ação imediata") -> 0 | M36: =COUNTIFS('BASE CONSOLIDADA'!$W$5:$W$129,1,'BASE CONSOLIDADA'!$G$5:$G$129,$J36,'BASE CONSOLIDADA'!$R$5:$R$129,"Validar cadastro") -> 0 | N36: =COUNTIFS('BASE CONSOLIDADA'!$W$5:$W$129,1,'BASE CONSOLIDADA'!$G$5:$G$129,$J36,'BASE CONSOLIDADA'!$R$5:$R$129,"Em tratamento") -> 0 | O36: =COUNTIFS('BASE CONSOLIDADA'!$W$5:$W$129,1,'BASE CONSOLIDADA'!$G$5:$G$129,$J36,'BASE CONSOLIDADA'!$R$5:$R$129,"Planejar revisão") -> 0 | P36: =COUNTIFS('BASE CONSOLIDADA'!$W$5:$W$129,1,'BASE CONSOLIDADA'!$G$5:$G$129,$J36,'BASE CONSOLIDADA'!$R$5:$R$129,"Regular") -> 3 | Q36: =COUNTIFS('BASE CONSOLIDADA'!$W$5:$W$129,1,'BASE CONSOLIDADA'!$G$5:$G$129,$J36,'BASE CONSOLIDADA'!$R$5:$R$129,"Inativo") -> 0 | S36: =IF('_AUX DASH'!$J$56="","",INDEX('_AUX DASH'!$K$50:$K$69,'_AUX DASH'!$J$56)) -> Elton Taborda | V36: =IF('_AUX DASH'!$J$56="","",INDEX('_AUX DASH'!$B$50:$B$69,'_AUX DASH'!$J$56)) -> 2 | W36: =IF('_AUX DASH'!$J$56="","",INDEX('_AUX DASH'!$C$50:$C$69,'_AUX DASH'!$J$56)) -> 0 | X36: =IF('_AUX DASH'!$J$56="","",INDEX('_AUX DASH'!$D$50:$D$69,'_AUX DASH'!$J$56)) -> 0 | Y36: =IF('_AUX DASH'!$J$56="","",INDEX('_AUX DASH'!$E$50:$E$69,'_AUX DASH'!$J$56)) -> 2
J37: Total | L37: =SUM(L30:L36) -> 1 | M37: =SUM(M30:M36) -> 2 | N37: =SUM(N30:N36) -> 3 | O37: =SUM(O30:O36) -> 12 | P37: =SUM(P30:P36) -> 104 | Q37: =SUM(Q30:Q36) -> 3 | S37: =IF('_AUX DASH'!$J$57="","",INDEX('_AUX DASH'!$K$50:$K$69,'_AUX DASH'!$J$57)) -> Lais Nascimento | V37: =IF('_AUX DASH'!$J$57="","",INDEX('_AUX DASH'!$B$50:$B$69,'_AUX DASH'!$J$57)) -> 2 | W37: =IF('_AUX DASH'!$J$57="","",INDEX('_AUX DASH'!$C$50:$C$69,'_AUX DASH'!$J$57)) -> 0 | X37: =IF('_AUX DASH'!$J$57="","",INDEX('_AUX DASH'!$D$50:$D$69,'_AUX DASH'!$J$57)) -> 0 | Y37: =IF('_AUX DASH'!$J$57="","",INDEX('_AUX DASH'!$E$50:$E$69,'_AUX DASH'!$J$57)) -> 1
S38: =COUNTIF('_AUX DASH'!$B$50:$B$69,">0")&" responsáveis com carteira · lista completa em _AUX DASH" -> 20 responsáveis com carteira · lista completa em _AUX DASH
B40: ▣ OUTROS CONTROLES DOCUMENTAIS · não somados aos KPIs de instruções
B41: NDocs FMG e ANX | E41: Documentos Transversais | I41: LPP | L41: AST AOL | P41: AST Geral | S41: RT's | W41: MO
B42: =COUNTA('NDocs FMG e ANX'!$B$3:$B$42) -> 38 | E42: =COUNTA('Documentos Transversais'!$B$3:$B$57) -> 51 | I42: =COUNTA(LPP!$A$3:$A$124) -> 122 | L42: =COUNTA('AST AOL'!$A$3:$A$43) -> 35 | P42: =COUNTA('AST Geral'!$A$3:$A$43) -> 23 | S42: =COUNTA('RT''s'!$B$3:$B$16) -> 9 | W42: =COUNTA(MO!$B$3:$B$20) -> 5
B43: =IF(SUMPRODUCT(--ISERROR('NDocs FMG e ANX'!$A$3:$N$42))>0,"⚠ "&SUMPRODUCT(--ISERROR('NDocs FMG e ANX'!$A$3:$N$42))&" erro(s) legado(s)","Abrir aba →") -> Abrir aba → | E43: =IF(SUMPRODUCT(--ISERROR('Documentos Transversais'!$A$3:$N$57))>0,"⚠ "&SUMPRODUCT(--ISERROR('Documentos Transversais'!$A$3:$N$57))&" erro(s) legado(s)","Abrir aba →") -> Abrir aba → | I43: =IF(SUMPRODUCT(--ISERROR(LPP!$A$3:$N$124))>0,"⚠ "&SUMPRODUCT(--ISERROR(LPP!$A$3:$N$124))&" erro(s) legado(s)","Abrir aba →") -> ⚠ 25 erro(s) legado(s) | L43: =IF(SUMPRODUCT(--ISERROR('AST AOL'!$A$3:$N$43))>0,"⚠ "&SUMPRODUCT(--ISERROR('AST AOL'!$A$3:$N$43))&" erro(s) legado(s)","Abrir aba →") -> Abrir aba → | P43: =IF(SUMPRODUCT(--ISERROR('AST Geral'!$A$3:$N$43))>0,"⚠ "&SUMPRODUCT(--ISERROR('AST Geral'!$A$3:$N$43))&" erro(s) legado(s)","Abrir aba →") -> ⚠ 1 erro(s) legado(s) | S43: =IF(SUMPRODUCT(--ISERROR('RT''s'!$A$3:$N$16))>0,"⚠ "&SUMPRODUCT(--ISERROR('RT''s'!$A$3:$N$16))&" erro(s) legado(s)","Abrir aba →") -> Abrir aba → | W43: =IF(SUMPRODUCT(--ISERROR(MO!$A$3:$N$20))>0,"⚠ "&SUMPRODUCT(--ISERROR(MO!$A$3:$N$20))&" erro(s) legado(s)","Abrir aba →") -> Abrir aba →
B45: Saúde documental = (Regular + Planejar revisão) ÷ instruções ativas. Ativas = todas, exceto Canceladas e Fora de Uso. Mede "quantas instruções em uso estão aprovadas e dentro da validade".
B46: Situação Gerencial é camada analítica: o Status oficial do NDocs é preservado na Base Consolidada (coluna E). Regras completas em QUALIDADE BASE › Regras.
B47: Contagem por Código NDocs único (125 códigos de 131 linhas de instrução). Documento compartilhado entre áreas conta uma vez; o filtro de Área inclui os compartilhados (ex.: Q4 inclui Q4/AOL).

Sheet PESQUISA
B2: ⌕ PESQUISA DE DOCUMENTO
B3: Localize por Código NDocs, número antigo (IT …) ou parte do título — sem diferenciar maiúsculas
B4: ⌂ Início | D4: ▦ Dashboard | F4: ⌕ Pesquisa | H4: ☰ Base | J4: ✓ Qualidade | K4: ▤ Outros
B5: DIGITE NA CAIXA ABAIXO E TECLE ENTER
B6: 🔍 | C6: Termo: | D6: OXIGÊNIO | F6: =IF(qBusca="","Digite um termo para pesquisar",COUNT('BASE CONSOLIDADA'!$Z$5:$Z$129)&" resultado(s) · exibindo até 15") -> 7 resultado(s) · exibindo até 15
B8: # | C8: Código NDocs | D8: Antigo nº | E8: Título | F8: Versão | G8: Status NDocs | H8: Validade | I8: Área | J8: Responsável | K8: Situação Gerencial
B9: =IF(COUNT('BASE CONSOLIDADA'!$Z$5:$Z$129)<1,"",1) -> 1 | C9: =IF($B9="","",INDEX('BASE CONSOLIDADA'!$A$1:$A$129,SMALL('BASE CONSOLIDADA'!$Z$5:$Z$129,$B9))) -> BRK-INS-01-016238-PT | D9: =IF($B9="","",INDEX('BASE CONSOLIDADA'!$C$1:$C$129,SMALL('BASE CONSOLIDADA'!$Z$5:$Z$129,$B9))) -> IT 5020-00175 | E9: =IF($B9="","",INDEX('BASE CONSOLIDADA'!$D$1:$D$129,SMALL('BASE CONSOLIDADA'!$Z$5:$Z$129,$B9))) -> DETERMINAÇÃO DE OXIGÊNIO EM GASES POR TELEDYNE | F9: =IF($B9="","",INDEX('BASE CONSOLIDADA'!$B$1:$B$129,SMALL('BASE CONSOLIDADA'!$Z$5:$Z$129,$B9))) -> 7.0 | G9: =IF($B9="","",INDEX('BASE CONSOLIDADA'!$E$1:$E$129,SMALL('BASE CONSOLIDADA'!$Z$5:$Z$129,$B9))) -> Aprovado | H9: =IF($B9="","",INDEX('BASE CONSOLIDADA'!$O$1:$O$129,SMALL('BASE CONSOLIDADA'!$Z$5:$Z$129,$B9))) -> 48104 | I9: =IF($B9="","",INDEX('BASE CONSOLIDADA'!$G$1:$G$129,SMALL('BASE CONSOLIDADA'!$Z$5:$Z$129,$B9))) -> Q4/AOL | J9: =IF($B9="","",INDEX('BASE CONSOLIDADA'!$P$1:$P$129,SMALL('BASE CONSOLIDADA'!$Z$5:$Z$129,$B9))) -> Ana Claudia Sergio De Oliveira | K9: =IF($B9="","",INDEX('BASE CONSOLIDADA'!$R$1:$R$129,SMALL('BASE CONSOLIDADA'!$Z$5:$Z$129,$B9))) -> Regular
B10: =IF(COUNT('BASE CONSOLIDADA'!$Z$5:$Z$129)<2,"",2) -> 2 | C10: =IF($B10="","",INDEX('BASE CONSOLIDADA'!$A$1:$A$129,SMALL('BASE CONSOLIDADA'!$Z$5:$Z$129,$B10))) -> BRK-INS-01-016427-PT | D10: =IF($B10="","",INDEX('BASE CONSOLIDADA'!$C$1:$C$129,SMALL('BASE CONSOLIDADA'!$Z$5:$Z$129,$B10))) -> IT 5020-00216 | E10: =IF($B10="","",INDEX('BASE CONSOLIDADA'!$D$1:$D$129,SMALL('BASE CONSOLIDADA'!$Z$5:$Z$129,$B10))) -> DETERMINAÇÃO DA DEMANDA QUÍMICA DE OXIGÊNIO EM ÁGUAS E EFLUENTES | F10: =IF($B10="","",INDEX('BASE CONSOLIDADA'!$B$1:$B$129,SMALL('BASE CONSOLIDADA'!$Z$5:$Z$129,$B10))) -> 9.0 | G10: =IF($B10="","",INDEX('BASE CONSOLIDADA'!$E$1:$E$129,SMALL('BASE CONSOLIDADA'!$Z$5:$Z$129,$B10))) -> Aprovado | H10: =IF($B10="","",INDEX('BASE CONSOLIDADA'!$O$1:$O$129,SMALL('BASE CONSOLIDADA'!$Z$5:$Z$129,$B10))) -> 46846 | I10: =IF($B10="","",INDEX('BASE CONSOLIDADA'!$G$1:$G$129,SMALL('BASE CONSOLIDADA'!$Z$5:$Z$129,$B10))) -> Q4 | J10: =IF($B10="","",INDEX('BASE CONSOLIDADA'!$P$1:$P$129,SMALL('BASE CONSOLIDADA'!$Z$5:$Z$129,$B10))) -> Ana Carla Da Cruz Araujo | K10: =IF($B10="","",INDEX('BASE CONSOLIDADA'!$R$1:$R$129,SMALL('BASE CONSOLIDADA'!$Z$5:$Z$129,$B10))) -> Regular
B11: =IF(COUNT('BASE CONSOLIDADA'!$Z$5:$Z$129)<3,"",3) -> 3 | C11: =IF($B11="","",INDEX('BASE CONSOLIDADA'!$A$1:$A$129,SMALL('BASE CONSOLIDADA'!$Z$5:$Z$129,$B11))) -> BRK-INS-01-016793-PT | D11: =IF($B11="","",INDEX('BASE CONSOLIDADA'!$C$1:$C$129,SMALL('BASE CONSOLIDADA'!$Z$5:$Z$129,$B11))) -> IT 6010-00078 | E11: =IF($B11="","",INDEX('BASE CONSOLIDADA'!$D$1:$D$129,SMALL('BASE CONSOLIDADA'!$Z$5:$Z$129,$B11))) -> DETERMINAÇÃO DE OXIGÊNIO EM GASES POR TELEDYNE MOD 3010 | F11: =IF($B11="","",INDEX('BASE CONSOLIDADA'!$B$1:$B$129,SMALL('BASE CONSOLIDADA'!$Z$5:$Z$129,$B11))) -> 5.0 | G11: =IF($B11="","",INDEX('BASE CONSOLIDADA'!$E$1:$E$129,SMALL('BASE CONSOLIDADA'!$Z$5:$Z$129,$B11))) -> Aprovado | H11: =IF($B11="","",INDEX('BASE CONSOLIDADA'!$O$1:$O$129,SMALL('BASE CONSOLIDADA'!$Z$5:$Z$129,$B11))) -> 46689 | I11: =IF($B11="","",INDEX('BASE CONSOLIDADA'!$G$1:$G$129,SMALL('BASE CONSOLIDADA'!$Z$5:$Z$129,$B11))) -> Q4/AOL | J11: =IF($B11="","",INDEX('BASE CONSOLIDADA'!$P$1:$P$129,SMALL('BASE CONSOLIDADA'!$Z$5:$Z$129,$B11))) -> Ana Claudia Sergio De Oliveira | K11: =IF($B11="","",INDEX('BASE CONSOLIDADA'!$R$1:$R$129,SMALL('BASE CONSOLIDADA'!$Z$5:$Z$129,$B11))) -> Regular
B12: =IF(COUNT('BASE CONSOLIDADA'!$Z$5:$Z$129)<4,"",4) -> 4 | C12: =IF($B12="","",INDEX('BASE CONSOLIDADA'!$A$1:$A$129,SMALL('BASE CONSOLIDADA'!$Z$5:$Z$129,$B12))) -> BRK-INS-01-011812-PT | D12: =IF($B12="","",INDEX('BASE CONSOLIDADA'!$C$1:$C$129,SMALL('BASE CONSOLIDADA'!$Z$5:$Z$129,$B12))) -> IT 5020-01340 | E12: =IF($B12="","",INDEX('BASE CONSOLIDADA'!$D$1:$D$129,SMALL('BASE CONSOLIDADA'!$Z$5:$Z$129,$B12))) -> DETERMINAÇÃO DE OXIGÊNIO PPM MOL EM GASES | F12: =IF($B12="","",INDEX('BASE CONSOLIDADA'!$B$1:$B$129,SMALL('BASE CONSOLIDADA'!$Z$5:$Z$129,$B12))) -> 6.0 | G12: =IF($B12="","",INDEX('BASE CONSOLIDADA'!$E$1:$E$129,SMALL('BASE CONSOLIDADA'!$Z$5:$Z$129,$B12))) -> Aprovado | H12: =IF($B12="","",INDEX('BASE CONSOLIDADA'!$O$1:$O$129,SMALL('BASE CONSOLIDADA'!$Z$5:$Z$129,$B12))) -> 47688 | I12: =IF($B12="","",INDEX('BASE CONSOLIDADA'!$G$1:$G$129,SMALL('BASE CONSOLIDADA'!$Z$5:$Z$129,$B12))) -> Q4 | J12: =IF($B12="","",INDEX('BASE CONSOLIDADA'!$P$1:$P$129,SMALL('BASE CONSOLIDADA'!$Z$5:$Z$129,$B12))) -> Camila Moraes De Oliveira | K12: =IF($B12="","",INDEX('BASE CONSOLIDADA'!$R$1:$R$129,SMALL('BASE CONSOLIDADA'!$Z$5:$Z$129,$B12))) -> Regular
B13: =IF(COUNT('BASE CONSOLIDADA'!$Z$5:$Z$129)<5,"",5) -> 5 | C13: =IF($B13="","",INDEX('BASE CONSOLIDADA'!$A$1:$A$129,SMALL('BASE CONSOLIDADA'!$Z$5:$Z$129,$B13))) -> BRK-INS-01-016681-PT | D13: =IF($B13="","",INDEX('BASE CONSOLIDADA'!$C$1:$C$129,SMALL('BASE CONSOLIDADA'!$Z$5:$Z$129,$B13))) -> IT 5030-02940-PT | E13: =IF($B13="","",INDEX('BASE CONSOLIDADA'!$D$1:$D$129,SMALL('BASE CONSOLIDADA'!$Z$5:$Z$129,$B13))) -> AJUSTECALIBRAÇÃO DOS ANALISADORES DE OXIGÊNIO DISSOLVIDO | F13: =IF($B13="","",INDEX('BASE CONSOLIDADA'!$B$1:$B$129,SMALL('BASE CONSOLIDADA'!$Z$5:$Z$129,$B13))) -> 3.0 | G13: =IF($B13="","",INDEX('BASE CONSOLIDADA'!$E$1:$E$129,SMALL('BASE CONSOLIDADA'!$Z$5:$Z$129,$B13))) -> Aprovado | H13: =IF($B13="","",INDEX('BASE CONSOLIDADA'!$O$1:$O$129,SMALL('BASE CONSOLIDADA'!$Z$5:$Z$129,$B13))) -> 48000 | I13: =IF($B13="","",INDEX('BASE CONSOLIDADA'!$G$1:$G$129,SMALL('BASE CONSOLIDADA'!$Z$5:$Z$129,$B13))) -> AOL | J13: =IF($B13="","",INDEX('BASE CONSOLIDADA'!$P$1:$P$129,SMALL('BASE CONSOLIDADA'!$Z$5:$Z$129,$B13))) -> Ana Claudia Sergio De Oliveira | K13: =IF($B13="","",INDEX('BASE CONSOLIDADA'!$R$1:$R$129,SMALL('BASE CONSOLIDADA'!$Z$5:$Z$129,$B13))) -> Regular
B14: =IF(COUNT('BASE CONSOLIDADA'!$Z$5:$Z$129)<6,"",6) -> 6 | C14: =IF($B14="","",INDEX('BASE CONSOLIDADA'!$A$1:$A$129,SMALL('BASE CONSOLIDADA'!$Z$5:$Z$129,$B14))) -> BRK-INS-01-016205-PT | D14: =IF($B14="","",INDEX('BASE CONSOLIDADA'!$C$1:$C$129,SMALL('BASE CONSOLIDADA'!$Z$5:$Z$129,$B14))) -> IT 5030-00248 | E14: =IF($B14="","",INDEX('BASE CONSOLIDADA'!$D$1:$D$129,SMALL('BASE CONSOLIDADA'!$Z$5:$Z$129,$B14))) -> AJUSTE E CALIBRAÇÃO DE ANALISADORES DE OXIGÊNIO DA SERVOMEX - DCX RJ | F14: =IF($B14="","",INDEX('BASE CONSOLIDADA'!$B$1:$B$129,SMALL('BASE CONSOLIDADA'!$Z$5:$Z$129,$B14))) -> 8.0 | G14: =IF($B14="","",INDEX('BASE CONSOLIDADA'!$E$1:$E$129,SMALL('BASE CONSOLIDADA'!$Z$5:$Z$129,$B14))) -> Aprovado | H14: =IF($B14="","",INDEX('BASE CONSOLIDADA'!$O$1:$O$129,SMALL('BASE CONSOLIDADA'!$Z$5:$Z$129,$B14))) -> 48104 | I14: =IF($B14="","",INDEX('BASE CONSOLIDADA'!$G$1:$G$129,SMALL('BASE CONSOLIDADA'!$Z$5:$Z$129,$B14))) -> AOL | J14: =IF($B14="","",INDEX('BASE CONSOLIDADA'!$P$1:$P$129,SMALL('BASE CONSOLIDADA'!$Z$5:$Z$129,$B14))) -> Ana Claudia Sergio De Oliveira | K14: =IF($B14="","",INDEX('BASE CONSOLIDADA'!$R$1:$R$129,SMALL('BASE CONSOLIDADA'!$Z$5:$Z$129,$B14))) -> Regular
B15: =IF(COUNT('BASE CONSOLIDADA'!$Z$5:$Z$129)<7,"",7) -> 7 | C15: =IF($B15="","",INDEX('BASE CONSOLIDADA'!$A$1:$A$129,SMALL('BASE CONSOLIDADA'!$Z$5:$Z$129,$B15))) -> BRK-INS-01-016748-PT | D15: =IF($B15="","",INDEX('BASE CONSOLIDADA'!$C$1:$C$129,SMALL('BASE CONSOLIDADA'!$Z$5:$Z$129,$B15))) -> IT 5030-02962-PT | E15: =IF($B15="","",INDEX('BASE CONSOLIDADA'!$D$1:$D$129,SMALL('BASE CONSOLIDADA'!$Z$5:$Z$129,$B15))) -> AJUSTE E CALIBRAÇÃO DOS ANALISADORES PORTÁTEIS DE OXIGÊNIO DISSOLVIDO | F15: =IF($B15="","",INDEX('BASE CONSOLIDADA'!$B$1:$B$129,SMALL('BASE CONSOLIDADA'!$Z$5:$Z$129,$B15))) -> 3.0 | G15: =IF($B15="","",INDEX('BASE CONSOLIDADA'!$E$1:$E$129,SMALL('BASE CONSOLIDADA'!$Z$5:$Z$129,$B15))) -> Aprovado | H15: =IF($B15="","",INDEX('BASE CONSOLIDADA'!$O$1:$O$129,SMALL('BASE CONSOLIDADA'!$Z$5:$Z$129,$B15))) -> 48008 | I15: =IF($B15="","",INDEX('BASE CONSOLIDADA'!$G$1:$G$129,SMALL('BASE CONSOLIDADA'!$Z$5:$Z$129,$B15))) -> AOL | J15: =IF($B15="","",INDEX('BASE CONSOLIDADA'!$P$1:$P$129,SMALL('BASE CONSOLIDADA'!$Z$5:$Z$129,$B15))) -> Ana Claudia Sergio De Oliveira | K15: =IF($B15="","",INDEX('BASE CONSOLIDADA'!$R$1:$R$129,SMALL('BASE CONSOLIDADA'!$Z$5:$Z$129,$B15))) -> Regular
B16: =IF(COUNT('BASE CONSOLIDADA'!$Z$5:$Z$129)<8,"",8) | C16: =IF($B16="","",INDEX('BASE CONSOLIDADA'!$A$1:$A$129,SMALL('BASE CONSOLIDADA'!$Z$5:$Z$129,$B16))) | D16: =IF($B16="","",INDEX('BASE CONSOLIDADA'!$C$1:$C$129,SMALL('BASE CONSOLIDADA'!$Z$5:$Z$129,$B16))) | E16: =IF($B16="","",INDEX('BASE CONSOLIDADA'!$D$1:$D$129,SMALL('BASE CONSOLIDADA'!$Z$5:$Z$129,$B16))) | F16: =IF($B16="","",INDEX('BASE CONSOLIDADA'!$B$1:$B$129,SMALL('BASE CONSOLIDADA'!$Z$5:$Z$129,$B16))) | G16: =IF($B16="","",INDEX('BASE CONSOLIDADA'!$E$1:$E$129,SMALL('BASE CONSOLIDADA'!$Z$5:$Z$129,$B16))) | H16: =IF($B16="","",INDEX('BASE CONSOLIDADA'!$O$1:$O$129,SMALL('BASE CONSOLIDADA'!$Z$5:$Z$129,$B16))) | I16: =IF($B16="","",INDEX('BASE CONSOLIDADA'!$G$1:$G$129,SMALL('BASE CONSOLIDADA'!$Z$5:$Z$129,$B16))) | J16: =IF($B16="","",INDEX('BASE CONSOLIDADA'!$P$1:$P$129,SMALL('BASE CONSOLIDADA'!$Z$5:$Z$129,$B16))) | K16: =IF($B16="","",INDEX('BASE CONSOLIDADA'!$R$1:$R$129,SMALL('BASE CONSOLIDADA'!$Z$5:$Z$129,$B16)))
B17: =IF(COUNT('BASE CONSOLIDADA'!$Z$5:$Z$129)<9,"",9) | C17: =IF($B17="","",INDEX('BASE CONSOLIDADA'!$A$1:$A$129,SMALL('BASE CONSOLIDADA'!$Z$5:$Z$129,$B17))) | D17: =IF($B17="","",INDEX('BASE CONSOLIDADA'!$C$1:$C$129,SMALL('BASE CONSOLIDADA'!$Z$5:$Z$129,$B17))) | E17: =IF($B17="","",INDEX('BASE CONSOLIDADA'!$D$1:$D$129,SMALL('BASE CONSOLIDADA'!$Z$5:$Z$129,$B17))) | F17: =IF($B17="","",INDEX('BASE CONSOLIDADA'!$B$1:$B$129,SMALL('BASE CONSOLIDADA'!$Z$5:$Z$129,$B17))) | G17: =IF($B17="","",INDEX('BASE CONSOLIDADA'!$E$1:$E$129,SMALL('BASE CONSOLIDADA'!$Z$5:$Z$129,$B17))) | H17: =IF($B17="","",INDEX('BASE CONSOLIDADA'!$O$1:$O$129,SMALL('BASE CONSOLIDADA'!$Z$5:$Z$129,$B17))) | I17: =IF($B17="","",INDEX('BASE CONSOLIDADA'!$G$1:$G$129,SMALL('BASE CONSOLIDADA'!$Z$5:$Z$129,$B17))) | J17: =IF($B17="","",INDEX('BASE CONSOLIDADA'!$P$1:$P$129,SMALL('BASE CONSOLIDADA'!$Z$5:$Z$129,$B17))) | K17: =IF($B17="","",INDEX('BASE CONSOLIDADA'!$R$1:$R$129,SMALL('BASE CONSOLIDADA'!$Z$5:$Z$129,$B17)))
B18: =IF(COUNT('BASE CONSOLIDADA'!$Z$5:$Z$129)<10,"",10) | C18: =IF($B18="","",INDEX('BASE CONSOLIDADA'!$A$1:$A$129,SMALL('BASE CONSOLIDADA'!$Z$5:$Z$129,$B18))) | D18: =IF($B18="","",INDEX('BASE CONSOLIDADA'!$C$1:$C$129,SMALL('BASE CONSOLIDADA'!$Z$5:$Z$129,$B18))) | E18: =IF($B18="","",INDEX('BASE CONSOLIDADA'!$D$1:$D$129,SMALL('BASE CONSOLIDADA'!$Z$5:$Z$129,$B18))) | F18: =IF($B18="","",INDEX('BASE CONSOLIDADA'!$B$1:$B$129,SMALL('BASE CONSOLIDADA'!$Z$5:$Z$129,$B18))) | G18: =IF($B18="","",INDEX('BASE CONSOLIDADA'!$E$1:$E$129,SMALL('BASE CONSOLIDADA'!$Z$5:$Z$129,$B18))) | H18: =IF($B18="","",INDEX('BASE CONSOLIDADA'!$O$1:$O$129,SMALL('BASE CONSOLIDADA'!$Z$5:$Z$129,$B18))) | I18: =IF($B18="","",INDEX('BASE CONSOLIDADA'!$G$1:$G$129,SMALL('BASE CONSOLIDADA'!$Z$5:$Z$129,$B18))) | J18: =IF($B18="","",INDEX('BASE CONSOLIDADA'!$P$1:$P$129,SMALL('BASE CONSOLIDADA'!$Z$5:$Z$129,$B18))) | K18: =IF($B18="","",INDEX('BASE CONSOLIDADA'!$R$1:$R$129,SMALL('BASE CONSOLIDADA'!$Z$5:$Z$129,$B18)))
B19: =IF(COUNT('BASE CONSOLIDADA'!$Z$5:$Z$129)<11,"",11) | C19: =IF($B19="","",INDEX('BASE CONSOLIDADA'!$A$1:$A$129,SMALL('BASE CONSOLIDADA'!$Z$5:$Z$129,$B19))) | D19: =IF($B19="","",INDEX('BASE CONSOLIDADA'!$C$1:$C$129,SMALL('BASE CONSOLIDADA'!$Z$5:$Z$129,$B19))) | E19: =IF($B19="","",INDEX('BASE CONSOLIDADA'!$D$1:$D$129,SMALL('BASE CONSOLIDADA'!$Z$5:$Z$129,$B19))) | F19: =IF($B19="","",INDEX('BASE CONSOLIDADA'!$B$1:$B$129,SMALL('BASE CONSOLIDADA'!$Z$5:$Z$129,$B19))) | G19: =IF($B19="","",INDEX('BASE CONSOLIDADA'!$E$1:$E$129,SMALL('BASE CONSOLIDADA'!$Z$5:$Z$129,$B19))) | H19: =IF($B19="","",INDEX('BASE CONSOLIDADA'!$O$1:$O$129,SMALL('BASE CONSOLIDADA'!$Z$5:$Z$129,$B19))) | I19: =IF($B19="","",INDEX('BASE CONSOLIDADA'!$G$1:$G$129,SMALL('BASE CONSOLIDADA'!$Z$5:$Z$129,$B19))) | J19: =IF($B19="","",INDEX('BASE CONSOLIDADA'!$P$1:$P$129,SMALL('BASE CONSOLIDADA'!$Z$5:$Z$129,$B19))) | K19: =IF($B19="","",INDEX('BASE CONSOLIDADA'!$R$1:$R$129,SMALL('BASE CONSOLIDADA'!$Z$5:$Z$129,$B19)))
B20: =IF(COUNT('BASE CONSOLIDADA'!$Z$5:$Z$129)<12,"",12) | C20: =IF($B20="","",INDEX('BASE CONSOLIDADA'!$A$1:$A$129,SMALL('BASE CONSOLIDADA'!$Z$5:$Z$129,$B20))) | D20: =IF($B20="","",INDEX('BASE CONSOLIDADA'!$C$1:$C$129,SMALL('BASE CONSOLIDADA'!$Z$5:$Z$129,$B20))) | E20: =IF($B20="","",INDEX('BASE CONSOLIDADA'!$D$1:$D$129,SMALL('BASE CONSOLIDADA'!$Z$5:$Z$129,$B20))) | F20: =IF($B20="","",INDEX('BASE CONSOLIDADA'!$B$1:$B$129,SMALL('BASE CONSOLIDADA'!$Z$5:$Z$129,$B20))) | G20: =IF($B20="","",INDEX('BASE CONSOLIDADA'!$E$1:$E$129,SMALL('BASE CONSOLIDADA'!$Z$5:$Z$129,$B20))) | H20: =IF($B20="","",INDEX('BASE CONSOLIDADA'!$O$1:$O$129,SMALL('BASE CONSOLIDADA'!$Z$5:$Z$129,$B20))) | I20: =IF($B20="","",INDEX('BASE CONSOLIDADA'!$G$1:$G$129,SMALL('BASE CONSOLIDADA'!$Z$5:$Z$129,$B20))) | J20: =IF($B20="","",INDEX('BASE CONSOLIDADA'!$P$1:$P$129,SMALL('BASE CONSOLIDADA'!$Z$5:$Z$129,$B20))) | K20: =IF($B20="","",INDEX('BASE CONSOLIDADA'!$R$1:$R$129,SMALL('BASE CONSOLIDADA'!$Z$5:$Z$129,$B20)))
B21: =IF(COUNT('BASE CONSOLIDADA'!$Z$5:$Z$129)<13,"",13) | C21: =IF($B21="","",INDEX('BASE CONSOLIDADA'!$A$1:$A$129,SMALL('BASE CONSOLIDADA'!$Z$5:$Z$129,$B21))) | D21: =IF($B21="","",INDEX('BASE CONSOLIDADA'!$C$1:$C$129,SMALL('BASE CONSOLIDADA'!$Z$5:$Z$129,$B21))) | E21: =IF($B21="","",INDEX('BASE CONSOLIDADA'!$D$1:$D$129,SMALL('BASE CONSOLIDADA'!$Z$5:$Z$129,$B21))) | F21: =IF($B21="","",INDEX('BASE CONSOLIDADA'!$B$1:$B$129,SMALL('BASE CONSOLIDADA'!$Z$5:$Z$129,$B21))) | G21: =IF($B21="","",INDEX('BASE CONSOLIDADA'!$E$1:$E$129,SMALL('BASE CONSOLIDADA'!$Z$5:$Z$129,$B21))) | H21: =IF($B21="","",INDEX('BASE CONSOLIDADA'!$O$1:$O$129,SMALL('BASE CONSOLIDADA'!$Z$5:$Z$129,$B21))) | I21: =IF($B21="","",INDEX('BASE CONSOLIDADA'!$G$1:$G$129,SMALL('BASE CONSOLIDADA'!$Z$5:$Z$129,$B21))) | J21: =IF($B21="","",INDEX('BASE CONSOLIDADA'!$P$1:$P$129,SMALL('BASE CONSOLIDADA'!$Z$5:$Z$129,$B21))) | K21: =IF($B21="","",INDEX('BASE CONSOLIDADA'!$R$1:$R$129,SMALL('BASE CONSOLIDADA'!$Z$5:$Z$129,$B21)))
B22: =IF(COUNT('BASE CONSOLIDADA'!$Z$5:$Z$129)<14,"",14) | C22: =IF($B22="","",INDEX('BASE CONSOLIDADA'!$A$1:$A$129,SMALL('BASE CONSOLIDADA'!$Z$5:$Z$129,$B22))) | D22: =IF($B22="","",INDEX('BASE CONSOLIDADA'!$C$1:$C$129,SMALL('BASE CONSOLIDADA'!$Z$5:$Z$129,$B22))) | E22: =IF($B22="","",INDEX('BASE CONSOLIDADA'!$D$1:$D$129,SMALL('BASE CONSOLIDADA'!$Z$5:$Z$129,$B22))) | F22: =IF($B22="","",INDEX('BASE CONSOLIDADA'!$B$1:$B$129,SMALL('BASE CONSOLIDADA'!$Z$5:$Z$129,$B22))) | G22: =IF($B22="","",INDEX('BASE CONSOLIDADA'!$E$1:$E$129,SMALL('BASE CONSOLIDADA'!$Z$5:$Z$129,$B22))) | H22: =IF($B22="","",INDEX('BASE CONSOLIDADA'!$O$1:$O$129,SMALL('BASE CONSOLIDADA'!$Z$5:$Z$129,$B22))) | I22: =IF($B22="","",INDEX('BASE CONSOLIDADA'!$G$1:$G$129,SMALL('BASE CONSOLIDADA'!$Z$5:$Z$129,$B22))) | J22: =IF($B22="","",INDEX('BASE CONSOLIDADA'!$P$1:$P$129,SMALL('BASE CONSOLIDADA'!$Z$5:$Z$129,$B22))) | K22: =IF($B22="","",INDEX('BASE CONSOLIDADA'!$R$1:$R$129,SMALL('BASE CONSOLIDADA'!$Z$5:$Z$129,$B22)))
B23: =IF(COUNT('BASE CONSOLIDADA'!$Z$5:$Z$129)<15,"",15) | C23: =IF($B23="","",INDEX('BASE CONSOLIDADA'!$A$1:$A$129,SMALL('BASE CONSOLIDADA'!$Z$5:$Z$129,$B23))) | D23: =IF($B23="","",INDEX('BASE CONSOLIDADA'!$C$1:$C$129,SMALL('BASE CONSOLIDADA'!$Z$5:$Z$129,$B23))) | E23: =IF($B23="","",INDEX('BASE CONSOLIDADA'!$D$1:$D$129,SMALL('BASE CONSOLIDADA'!$Z$5:$Z$129,$B23))) | F23: =IF($B23="","",INDEX('BASE CONSOLIDADA'!$B$1:$B$129,SMALL('BASE CONSOLIDADA'!$Z$5:$Z$129,$B23))) | G23: =IF($B23="","",INDEX('BASE CONSOLIDADA'!$E$1:$E$129,SMALL('BASE CONSOLIDADA'!$Z$5:$Z$129,$B23))) | H23: =IF($B23="","",INDEX('BASE CONSOLIDADA'!$O$1:$O$129,SMALL('BASE CONSOLIDADA'!$Z$5:$Z$129,$B23))) | I23: =IF($B23="","",INDEX('BASE CONSOLIDADA'!$G$1:$G$129,SMALL('BASE CONSOLIDADA'!$Z$5:$Z$129,$B23))) | J23: =IF($B23="","",INDEX('BASE CONSOLIDADA'!$P$1:$P$129,SMALL('BASE CONSOLIDADA'!$Z$5:$Z$129,$B23))) | K23: =IF($B23="","",INDEX('BASE CONSOLIDADA'!$R$1:$R$129,SMALL('BASE CONSOLIDADA'!$Z$5:$Z$129,$B23)))
B25: Dica: digite só o número (ex.: 016238 ou 5020-00217) ou uma palavra do título. Apague o termo para limpar. Detalhes completos na Base Consolidada.

Sheet BASE CONSOLIDADA
A1: BASE CONSOLIDADA DE INSTRUÇÕES | E1: ⌂ Início | F1: ▦ Dashboard | H1: ⌕ Pesquisa | I1: ✓ Qualidade
A2: ="LCQ RJ · "&COUNTA('BASE CONSOLIDADA'!$A$5:$A$129)&" códigos únicos consolidados de NDocs Q4, PE_PP, AOL e COMUNS" -> LCQ RJ · 125 códigos únicos consolidados de NDocs Q4, PE_PP, AOL e COMUNS
A3: ▌ DADO ORIGINAL NDocs — copiado da aba indicada em "Origem", sem edição | N3: ▌ CAMADA ANALÍTICA — fórmulas, não editar
A4: Código NDocs | B4: Versão | C4: Antigo Número | D4: Título | E4: Status NDocs | F4: Validade | G4: Área consolidada | H4: Abrangência | I4: Responsável | J4: Norma | K4: Comentários | L4: Origem (aba!linha) | M4: Qtd. registros origem | N4: Status padronizado | O4: Validade (analítica) | P4: Responsável padronizado | Q4: Dias p/ vencer | R4: Situação Gerencial | S4: Horizonte de validade | T4: Mês de vencimento | U4: Prioridade | V4: Ação recomendada | W4: Filtro dashboard | X4: Score ação | Y4: Chave de busca | Z4: Busca (linha)
A5: BRK-INS-01-010015-PT | B5: 7.0 | C5: IT 5020-00217 | D5: DETERMINAÇÃO DA CONCENTRAÇÃO DE SULFETO | E5: Aprovado | F5: 46689 | G5: Q4 | I5: Ana CARLA DA CRUZ ARAUJO | J5: UOP 163 - HYDROGEN SULFIDE AND MERCAPTAN SULFUR IN LIQUID HYDROCARBONS BY POTENTIOMETRIC TITRATION | L5: NDocs Q4!3 | M5: 1 | N5: =IF(TRIM(SUBSTITUTE(E5,CHAR(160)," "))="Avaiação de uso","Avaliação de uso",IF(TRIM(SUBSTITUTE(E5,CHAR(160)," "))="Cancelada","Cancelado",TRIM(SUBSTITUTE(E5,CHAR(160)," ")))) -> Aprovado | O5: =IF(ISNUMBER(F5),F5,IFERROR(DATE(RIGHT(RIGHT(TRIM(F5),10),4),MID(RIGHT(TRIM(F5),10),4,2),LEFT(RIGHT(TRIM(F5),10),2)),"")) -> 46689 | P5: =PROPER(TRIM(SUBSTITUTE(I5,CHAR(160)," "))) -> Ana Carla Da Cruz Araujo | Q5: =IF(O5="","",O5-DataRef) -> 388 | R5: =IF(OR(N5="Cancelado",N5="Fora de Uso"),"Inativo",IF(OR(N5="Revisão",N5="Em Elaboração"),"Em tratamento",IF(OR(N5<>"Aprovado",O5=""),"Validar cadastro",IF(O5<DataRef,"Ação imediata",IF(O5<=EDATE(DataRef,12),"Planejar revisão","Regular"))))) -> Regular | S5: =IF(R5="Inativo","Inativo",IF(O5="","Sem validade",IF(O5<DataRef,"Vencida",IF(O5<=DataRef+90,"Até 90 dias",IF(O5<=EDATE(DataRef,12),"91 dias a 12 meses","Após 12 meses"))))) -> Após 12 meses | T5: =IF(O5="","",DATE(YEAR(O5),MONTH(O5),1)) -> 46661 | U5: =IF(R5="Ação imediata",1,IF(N5="Não encontrado",2,IF(N5="Revisão",3,IF(N5="Em Elaboração",4,IF(S5="Até 90 dias",5,IF(R5="Validar cadastro",6,0)))))) -> 0 | V5: =CHOOSE(U5+1,IF(R5="Planejar revisão","Incluir no plano anual de revisão",IF(R5="Inativo","Sem ação","Monitorar")),"Revisar ou prorrogar validade","Confirmar status no NDocs","Acompanhar revisão","Concluir elaboração","Iniciar revisão (≤ 90 dias)","Validar aplicabilidade") -> Monitorar | W5: =(OR(fArea="Todas",ISNUMBER(SEARCH(fArea,G5))))*(OR(fStatus="Todos",N5=fStatus))*(OR(fSit="Todas",R5=fSit))*(OR(fResp="Todos",P5=fResp))*(OR(fHor="Todos",S5=fHor)) -> 1 | X5: =IF(AND(W5=1,U5>0),(7-U5)*100000+50000-IF(ISNUMBER(Q5),Q5,0)+ROW()/1000,0) -> 0 | Y5: =UPPER(A5&" "&TRIM(SUBSTITUTE(C5,CHAR(160)," "))&" "&TRIM(SUBSTITUTE(D5,CHAR(160)," "))) -> BRK-INS-01-010015-PT IT 5020-00217 DETERMINAÇÃO DA CONCENTRAÇÃO DE SULFETO | Z5: =IF(qBusca="","",IF(ISNUMBER(SEARCH(TRIM(qBusca),Y5)),ROW(),""))
A6: BRK-INS-01-010021-PT | B6: 7.0 | C6: IT 5020-00219 | D6: DETERMINAÇÃO DA TURBIDEZ | E6: Aprovado | F6: 48008 | G6: Q4 | I6: LARISSA VICENTE CARDOSO GUEDES | L6: NDocs Q4!4 | M6: 1 | N6: =IF(TRIM(SUBSTITUTE(E6,CHAR(160)," "))="Avaiação de uso","Avaliação de uso",IF(TRIM(SUBSTITUTE(E6,CHAR(160)," "))="Cancelada","Cancelado",TRIM(SUBSTITUTE(E6,CHAR(160)," ")))) -> Aprovado | O6: =IF(ISNUMBER(F6),F6,IFERROR(DATE(RIGHT(RIGHT(TRIM(F6),10),4),MID(RIGHT(TRIM(F6),10),4,2),LEFT(RIGHT(TRIM(F6),10),2)),"")) -> 48008 | P6: =PROPER(TRIM(SUBSTITUTE(I6,CHAR(160)," "))) -> Larissa Vicente Cardoso Guedes | Q6: =IF(O6="","",O6-DataRef) -> 1707 | R6: =IF(OR(N6="Cancelado",N6="Fora de Uso"),"Inativo",IF(OR(N6="Revisão",N6="Em Elaboração"),"Em tratamento",IF(OR(N6<>"Aprovado",O6=""),"Validar cadastro",IF(O6<DataRef,"Ação imediata",IF(O6<=EDATE(DataRef,12),"Planejar revisão","Regular"))))) -> Regular | S6: =IF(R6="Inativo","Inativo",IF(O6="","Sem validade",IF(O6<DataRef,"Vencida",IF(O6<=DataRef+90,"Até 90 dias",IF(O6<=EDATE(DataRef,12),"91 dias a 12 meses","Após 12 meses"))))) -> Após 12 meses | T6: =IF(O6="","",DATE(YEAR(O6),MONTH(O6),1)) -> 48000 | U6: =IF(R6="Ação imediata",1,IF(N6="Não encontrado",2,IF(N6="Revisão",3,IF(N6="Em Elaboração",4,IF(S6="Até 90 dias",5,IF(R6="Validar cadastro",6,0)))))) -> 0 | V6: =CHOOSE(U6+1,IF(R6="Planejar revisão","Incluir no plano anual de revisão",IF(R6="Inativo","Sem ação","Monitorar")),"Revisar ou prorrogar validade","Confirmar status no NDocs","Acompanhar revisão","Concluir elaboração","Iniciar revisão (≤ 90 dias)","Validar aplicabilidade") -> Monitorar | W6: =(OR(fArea="Todas",ISNUMBER(SEARCH(fArea,G6))))*(OR(fStatus="Todos",N6=fStatus))*(OR(fSit="Todas",R6=fSit))*(OR(fResp="Todos",P6=fResp))*(OR(fHor="Todos",S6=fHor)) -> 1 | X6: =IF(AND(W6=1,U6>0),(7-U6)*100000+50000-IF(ISNUMBER(Q6),Q6,0)+ROW()/1000,0) -> 0 | Y6: =UPPER(A6&" "&TRIM(SUBSTITUTE(C6,CHAR(160)," "))&" "&TRIM(SUBSTITUTE(D6,CHAR(160)," "))) -> BRK-INS-01-010021-PT IT 5020-00219 DETERMINAÇÃO DA TURBIDEZ | Z6: =IF(qBusca="","",IF(ISNUMBER(SEARCH(TRIM(qBusca),Y6)),ROW(),""))
A7: BRK-INS-01-010028-PT | B7: 7.0 | C7: IT 5020-00220 | D7: DETERMINAÇÃO DA CONCENTRAÇÃO DE CLORO RESIDUAL LIVRE | E7: Aprovado | F7: 46846 | G7: Q4 | I7: Ana CARLA DA CRUZ ARAUJO | L7: NDocs Q4!5 | M7: 1 | N7: =IF(TRIM(SUBSTITUTE(E7,CHAR(160)," "))="Avaiação de uso","Avaliação de uso",IF(TRIM(SUBSTITUTE(E7,CHAR(160)," "))="Cancelada","Cancelado",TRIM(SUBSTITUTE(E7,CHAR(160)," ")))) -> Aprovado | O7: =IF(ISNUMBER(F7),F7,IFERROR(DATE(RIGHT(RIGHT(TRIM(F7),10),4),MID(RIGHT(TRIM(F7),10),4,2),LEFT(RIGHT(TRIM(F7),10),2)),"")) -> 46846 | P7: =PROPER(TRIM(SUBSTITUTE(I7,CHAR(160)," "))) -> Ana Carla Da Cruz Araujo | Q7: =IF(O7="","",O7-DataRef) -> 545 | R7: =IF(OR(N7="Cancelado",N7="Fora de Uso"),"Inativo",IF(OR(N7="Revisão",N7="Em Elaboração"),"Em tratamento",IF(OR(N7<>"Aprovado",O7=""),"Validar cadastro",IF(O7<DataRef,"Ação imediata",IF(O7<=EDATE(DataRef,12),"Planejar revisão","Regular"))))) -> Regular | S7: =IF(R7="Inativo","Inativo",IF(O7="","Sem validade",IF(O7<DataRef,"Vencida",IF(O7<=DataRef+90,"Até 90 dias",IF(O7<=EDATE(DataRef,12),"91 dias a 12 meses","Após 12 meses"))))) -> Após 12 meses | T7: =IF(O7="","",DATE(YEAR(O7),MONTH(O7),1)) -> 46844 | U7: =IF(R7="Ação imediata",1,IF(N7="Não encontrado",2,IF(N7="Revisão",3,IF(N7="Em Elaboração",4,IF(S7="Até 90 dias",5,IF(R7="Validar cadastro",6,0)))))) -> 0 | V7: =CHOOSE(U7+1,IF(R7="Planejar revisão","Incluir no plano anual de revisão",IF(R7="Inativo","Sem ação","Monitorar")),"Revisar ou prorrogar validade","Confirmar status no NDocs","Acompanhar revisão","Concluir elaboração","Iniciar revisão (≤ 90 dias)","Validar aplicabilidade") -> Monitorar | W7: =(OR(fArea="Todas",ISNUMBER(SEARCH(fArea,G7))))*(OR(fStatus="Todos",N7=fStatus))*(OR(fSit="Todas",R7=fSit))*(OR(fResp="Todos",P7=fResp))*(OR(fHor="Todos",S7=fHor)) -> 1 | X7: =IF(AND(W7=1,U7>0),(7-U7)*100000+50000-IF(ISNUMBER(Q7),Q7,0)+ROW()/1000,0) -> 0 | Y7: =UPPER(A7&" "&TRIM(SUBSTITUTE(C7,CHAR(160)," "))&" "&TRIM(SUBSTITUTE(D7,CHAR(160)," "))) -> BRK-INS-01-010028-PT IT 5020-00220 DETERMINAÇÃO DA CONCENTRAÇÃO DE CLORO RESIDUAL LIVRE | Z7: =IF(qBusca="","",IF(ISNUMBER(SEARCH(TRIM(qBusca),Y7)),ROW(),""))
A8: BRK-INS-01-010035-PT | B8: 6.0 | C8: IT 5020-00221 | D8: DETERMINAÇÃO DA CONCENTRAÇÃO DE NAOH E NA2CO3 | E8: Aprovado | F8: 46846 | G8: Q4 | I8: Ana CARLA DA CRUZ ARAUJO | J8: ASTM D5580; ABNT NBR 8140 - SODA CÁUSTICA LÍQUIDA - DETERMINAÇÃO DA ALCALINIDADE TOTAL - MÉTODO POTENCIOMÉTRICO/VOLUMÉTRICO | L8: NDocs Q4!6 | M8: 1 | N8: =IF(TRIM(SUBSTITUTE(E8,CHAR(160)," "))="Avaiação de uso","Avaliação de uso",IF(TRIM(SUBSTITUTE(E8,CHAR(160)," "))="Cancelada","Cancelado",TRIM(SUBSTITUTE(E8,CHAR(160)," ")))) -> Aprovado | O8: =IF(ISNUMBER(F8),F8,IFERROR(DATE(RIGHT(RIGHT(TRIM(F8),10),4),MID(RIGHT(TRIM(F8),10),4,2),LEFT(RIGHT(TRIM(F8),10),2)),"")) -> 46846 | P8: =PROPER(TRIM(SUBSTITUTE(I8,CHAR(160)," "))) -> Ana Carla Da Cruz Araujo | Q8: =IF(O8="","",O8-DataRef) -> 545 | R8: =IF(OR(N8="Cancelado",N8="Fora de Uso"),"Inativo",IF(OR(N8="Revisão",N8="Em Elaboração"),"Em tratamento",IF(OR(N8<>"Aprovado",O8=""),"Validar cadastro",IF(O8<DataRef,"Ação imediata",IF(O8<=EDATE(DataRef,12),"Planejar revisão","Regular"))))) -> Regular | S8: =IF(R8="Inativo","Inativo",IF(O8="","Sem validade",IF(O8<DataRef,"Vencida",IF(O8<=DataRef+90,"Até 90 dias",IF(O8<=EDATE(DataRef,12),"91 dias a 12 meses","Após 12 meses"))))) -> Após 12 meses | T8: =IF(O8="","",DATE(YEAR(O8),MONTH(O8),1)) -> 46844 | U8: =IF(R8="Ação imediata",1,IF(N8="Não encontrado",2,IF(N8="Revisão",3,IF(N8="Em Elaboração",4,IF(S8="Até 90 dias",5,IF(R8="Validar cadastro",6,0)))))) -> 0 | V8: =CHOOSE(U8+1,IF(R8="Planejar revisão","Incluir no plano anual de revisão",IF(R8="Inativo","Sem ação","Monitorar")),"Revisar ou prorrogar validade","Confirmar status no NDocs","Acompanhar revisão","Concluir elaboração","Iniciar revisão (≤ 90 dias)","Validar aplicabilidade") -> Monitorar | W8: =(OR(fArea="Todas",ISNUMBER(SEARCH(fArea,G8))))*(OR(fStatus="Todos",N8=fStatus))*(OR(fSit="Todas",R8=fSit))*(OR(fResp="Todos",P8=fResp))*(OR(fHor="Todos",S8=fHor)) -> 1 | X8: =IF(AND(W8=1,U8>0),(7-U8)*100000+50000-IF(ISNUMBER(Q8),Q8,0)+ROW()/1000,0) -> 0 | Y8: =UPPER(A8&" "&TRIM(SUBSTITUTE(C8,CHAR(160)," "))&" "&TRIM(SUBSTITUTE(D8,CHAR(160)," "))) -> BRK-INS-01-010035-PT IT 5020-00221 DETERMINAÇÃO DA CONCENTRAÇÃO DE NAOH E NA2CO3 | Z8: =IF(qBusca="","",IF(ISNUMBER(SEARCH(TRIM(qBusca),Y8)),ROW(),""))
A9: BRK-INS-01-010039-PT | B9: 6.0 | C9: IT 5020-00222 | D9: DETERMINAÇÃO DA TEMPERATURA | E9: Aprovado | F9: 46730 | G9: Q4 | I9: Ana CARLA DA CRUZ ARAUJO | L9: NDocs Q4!7 | M9: 1 | N9: =IF(TRIM(SUBSTITUTE(E9,CHAR(160)," "))="Avaiação de uso","Avaliação de uso",IF(TRIM(SUBSTITUTE(E9,CHAR(160)," "))="Cancelada","Cancelado",TRIM(SUBSTITUTE(E9,CHAR(160)," ")))) -> Aprovado | O9: =IF(ISNUMBER(F9),F9,IFERROR(DATE(RIGHT(RIGHT(TRIM(F9),10),4),MID(RIGHT(TRIM(F9),10),4,2),LEFT(RIGHT(TRIM(F9),10),2)),"")) -> 46730 | P9: =PROPER(TRIM(SUBSTITUTE(I9,CHAR(160)," "))) -> Ana Carla Da Cruz Araujo | Q9: =IF(O9="","",O9-DataRef) -> 429 | R9: =IF(OR(N9="Cancelado",N9="Fora de Uso"),"Inativo",IF(OR(N9="Revisão",N9="Em Elaboração"),"Em tratamento",IF(OR(N9<>"Aprovado",O9=""),"Validar cadastro",IF(O9<DataRef,"Ação imediata",IF(O9<=EDATE(DataRef,12),"Planejar revisão","Regular"))))) -> Regular | S9: =IF(R9="Inativo","Inativo",IF(O9="","Sem validade",IF(O9<DataRef,"Vencida",IF(O9<=DataRef+90,"Até 90 dias",IF(O9<=EDATE(DataRef,12),"91 dias a 12 meses","Após 12 meses"))))) -> Após 12 meses | T9: =IF(O9="","",DATE(YEAR(O9),MONTH(O9),1)) -> 46722 | U9: =IF(R9="Ação imediata",1,IF(N9="Não encontrado",2,IF(N9="Revisão",3,IF(N9="Em Elaboração",4,IF(S9="Até 90 dias",5,IF(R9="Validar cadastro",6,0)))))) -> 0 | V9: =CHOOSE(U9+1,IF(R9="Planejar revisão","Incluir no plano anual de revisão",IF(R9="Inativo","Sem ação","Monitorar")),"Revisar ou prorrogar validade","Confirmar status no NDocs","Acompanhar revisão","Concluir elaboração","Iniciar revisão (≤ 90 dias)","Validar aplicabilidade") -> Monitorar | W9: =(OR(fArea="Todas",ISNUMBER(SEARCH(fArea,G9))))*(OR(fStatus="Todos",N9=fStatus))*(OR(fSit="Todas",R9=fSit))*(OR(fResp="Todos",P9=fResp))*(OR(fHor="Todos",S9=fHor)) -> 1 | X9: =IF(AND(W9=1,U9>0),(7-U9)*100000+50000-IF(ISNUMBER(Q9),Q9,0)+ROW()/1000,0) -> 0 | Y9: =UPPER(A9&" "&TRIM(SUBSTITUTE(C9,CHAR(160)," "))&" "&TRIM(SUBSTITUTE(D9,CHAR(160)," "))) -> BRK-INS-01-010039-PT IT 5020-00222 DETERMINAÇÃO DA TEMPERATURA | Z9: =IF(qBusca="","",IF(ISNUMBER(SEARCH(TRIM(qBusca),Y9)),ROW(),""))
A10: BRK-INS-01-010051-PT | B10: 6.0 | C10: IT 5020-00225 | D10: DETERMINAÇÃO DO PH | E10: Aprovado | F10: 46689 | G10: Q4 | I10: Ana CARLA DA CRUZ ARAUJO | J10: ASTM D1293 | L10: NDocs Q4!8 | M10: 1 | N10: =IF(TRIM(SUBSTITUTE(E10,CHAR(160)," "))="Avaiação de uso","Avaliação de uso",IF(TRIM(SUBSTITUTE(E10,CHAR(160)," "))="Cancelada","Cancelado",TRIM(SUBSTITUTE(E10,CHAR(160)," ")))) -> Aprovado | O10: =IF(ISNUMBER(F10),F10,IFERROR(DATE(RIGHT(RIGHT(TRIM(F10),10),4),MID(RIGHT(TRIM(F10),10),4,2),LEFT(RIGHT(TRIM(F10),10),2)),"")) -> 46689 | P10: =PROPER(TRIM(SUBSTITUTE(I10,CHAR(160)," "))) -> Ana Carla Da Cruz Araujo | Q10: =IF(O10="","",O10-DataRef) -> 388 | R10: =IF(OR(N10="Cancelado",N10="Fora de Uso"),"Inativo",IF(OR(N10="Revisão",N10="Em Elaboração"),"Em tratamento",IF(OR(N10<>"Aprovado",O10=""),"Validar cadastro",IF(O10<DataRef,"Ação imediata",IF(O10<=EDATE(DataRef,12),"Planejar revisão","Regular"))))) -> Regular | S10: =IF(R10="Inativo","Inativo",IF(O10="","Sem validade",IF(O10<DataRef,"Vencida",IF(O10<=DataRef+90,"Até 90 dias",IF(O10<=EDATE(DataRef,12),"91 dias a 12 meses","Após 12 meses"))))) -> Após 12 meses | T10: =IF(O10="","",DATE(YEAR(O10),MONTH(O10),1)) -> 46661 | U10: =IF(R10="Ação imediata",1,IF(N10="Não encontrado",2,IF(N10="Revisão",3,IF(N10="Em Elaboração",4,IF(S10="Até 90 dias",5,IF(R10="Validar cadastro",6,0)))))) -> 0 | V10: =CHOOSE(U10+1,IF(R10="Planejar revisão","Incluir no plano anual de revisão",IF(R10="Inativo","Sem ação","Monitorar")),"Revisar ou prorrogar validade","Confirmar status no NDocs","Acompanhar revisão","Concluir elaboração","Iniciar revisão (≤ 90 dias)","Validar aplicabilidade") -> Monitorar | W10: =(OR(fArea="Todas",ISNUMBER(SEARCH(fArea,G10))))*(OR(fStatus="Todos",N10=fStatus))*(OR(fSit="Todas",R10=fSit))*(OR(fResp="Todos",P10=fResp))*(OR(fHor="Todos",S10=fHor)) -> 1 | X10: =IF(AND(W10=1,U10>0),(7-U10)*100000+50000-IF(ISNUMBER(Q10),Q10,0)+ROW()/1000,0) -> 0 | Y10: =UPPER(A10&" "&TRIM(SUBSTITUTE(C10,CHAR(160)," "))&" "&TRIM(SUBSTITUTE(D10,CHAR(160)," "))) -> BRK-INS-01-010051-PT IT 5020-00225 DETERMINAÇÃO DO PH | Z10: =IF(qBusca="","",IF(ISNUMBER(SEARCH(TRIM(qBusca),Y10)),ROW(),""))
A11: BRK-INS-01-010064-PT | B11: 8.0 | C11: IT 5020-00228 | D11: PREPARO DE PADRÕES E SOLUÇÕES DO LCQ DCX - Q4, PE9 E PP5. | E11: Aprovado | F11: 46846 | G11: Q4 | I11: Ana CARLA DA CRUZ ARAUJO | L11: NDocs Q4!9 | M11: 1 | N11: =IF(TRIM(SUBSTITUTE(E11,CHAR(160)," "))="Avaiação de uso","Avaliação de uso",IF(TRIM(SUBSTITUTE(E11,CHAR(160)," "))="Cancelada","Cancelado",TRIM(SUBSTITUTE(E11,CHAR(160)," ")))) -> Aprovado | O11: =IF(ISNUMBER(F11),F11,IFERROR(DATE(RIGHT(RIGHT(TRIM(F11),10),4),MID(RIGHT(TRIM(F11),10),4,2),LEFT(RIGHT(TRIM(F11),10),2)),"")) -> 46846 | P11: =PROPER(TRIM(SUBSTITUTE(I11,CHAR(160)," "))) -> Ana Carla Da Cruz Araujo | Q11: =IF(O11="","",O11-DataRef) -> 545 | R11: =IF(OR(N11="Cancelado",N11="Fora de Uso"),"Inativo",IF(OR(N11="Revisão",N11="Em Elaboração"),"Em tratamento",IF(OR(N11<>"Aprovado",O11=""),"Validar cadastro",IF(O11<DataRef,"Ação imediata",IF(O11<=EDATE(DataRef,12),"Planejar revisão","Regular"))))) -> Regular | S11: =IF(R11="Inativo","Inativo",IF(O11="","Sem validade",IF(O11<DataRef,"Vencida",IF(O11<=DataRef+90,"Até 90 dias",IF(O11<=EDATE(DataRef,12),"91 dias a 12 meses","Após 12 meses"))))) -> Após 12 meses | T11: =IF(O11="","",DATE(YEAR(O11),MONTH(O11),1)) -> 46844 | U11: =IF(R11="Ação imediata",1,IF(N11="Não encontrado",2,IF(N11="Revisão",3,IF(N11="Em Elaboração",4,IF(S11="Até 90 dias",5,IF(R11="Validar cadastro",6,0)))))) -> 0 | V11: =CHOOSE(U11+1,IF(R11="Planejar revisão","Incluir no plano anual de revisão",IF(R11="Inativo","Sem ação","Monitorar")),"Revisar ou prorrogar validade","Confirmar status no NDocs","Acompanhar revisão","Concluir elaboração","Iniciar revisão (≤ 90 dias)","Validar aplicabilidade") -> Monitorar | W11: =(OR(fArea="Todas",ISNUMBER(SEARCH(fArea,G11))))*(OR(fStatus="Todos",N11=fStatus))*(OR(fSit="Todas",R11=fSit))*(OR(fResp="Todos",P11=fResp))*(OR(fHor="Todos",S11=fHor)) -> 1 | X11: =IF(AND(W11=1,U11>0),(7-U11)*100000+50000-IF(ISNUMBER(Q11),Q11,0)+ROW()/1000,0) -> 0 | Y11: =UPPER(A11&" "&TRIM(SUBSTITUTE(C11,CHAR(160)," "))&" "&TRIM(SUBSTITUTE(D11,CHAR(160)," "))) -> BRK-INS-01-010064-PT IT 5020-00228 PREPARO DE PADRÕES E SOLUÇÕES DO LCQ DCX - Q4, PE9 E PP5. | Z11: =IF(qBusca="","",IF(ISNUMBER(SEARCH(TRIM(qBusca),Y11)),ROW(),""))
